{"uid":"388113e9603970f6","name":"test_given_sdcore_terraform_module_when_deploy_then_status_is_active","fullName":"tests.integration.test_integration.TestSDCoreBundle#test_given_sdcore_terraform_module_when_deploy_then_status_is_active","historyId":"5abf18a073330975d0499b6d3bc096cd","time":{"start":1740277741190,"stop":1740278047959,"duration":306769},"status":"broken","statusMessage":"tests.integration.terraform_helper.TerraformError: Error running `terraform apply`","statusTrace":"Traceback (most recent call last):\n  File \"/home/ubuntu/actions-runner/_work/sdcore-tests/sdcore-tests/tests/integration/terraform_helper.py\", line 74, in apply\n    self._run_terraform_cmd(TerraformCommands.apply, *args)\n  File \"/home/ubuntu/actions-runner/_work/sdcore-tests/sdcore-tests/tests/integration/terraform_helper.py\", line 100, in _run_terraform_cmd\n    return check_call([TERRAFORM_APP_NAME, terraform_command, *args], cwd=self.work_dir)\n  File \"/usr/lib/python3.10/subprocess.py\", line 369, in check_call\n    raise CalledProcessError(retcode, cmd)\nsubprocess.CalledProcessError: Command '['terraform', <TerraformCommands.apply: 'apply'>, '-auto-approve']' returned non-zero exit status 1.\n\nThe above exception was the direct cause of the following exception:\n\nTraceback (most recent call last):\n  File \"/home/ubuntu/actions-runner/_work/sdcore-tests/sdcore-tests/.tox/integration/lib/python3.10/site-packages/_pytest/runner.py\", line 341, in from_call\n    result: TResult | None = func()\n  File \"/home/ubuntu/actions-runner/_work/sdcore-tests/sdcore-tests/.tox/integration/lib/python3.10/site-packages/_pytest/runner.py\", line 242, in <lambda>\n    lambda: runtest_hook(item=item, **kwds), when=when, reraise=reraise\n  File \"/home/ubuntu/actions-runner/_work/sdcore-tests/sdcore-tests/.tox/integration/lib/python3.10/site-packages/pluggy/_hooks.py\", line 513, in __call__\n    return self._hookexec(self.name, self._hookimpls.copy(), kwargs, firstresult)\n  File \"/home/ubuntu/actions-runner/_work/sdcore-tests/sdcore-tests/.tox/integration/lib/python3.10/site-packages/pluggy/_manager.py\", line 120, in _hookexec\n    return self._inner_hookexec(hook_name, methods, kwargs, firstresult)\n  File \"/home/ubuntu/actions-runner/_work/sdcore-tests/sdcore-tests/.tox/integration/lib/python3.10/site-packages/pluggy/_callers.py\", line 182, in _multicall\n    return outcome.get_result()\n  File \"/home/ubuntu/actions-runner/_work/sdcore-tests/sdcore-tests/.tox/integration/lib/python3.10/site-packages/pluggy/_result.py\", line 100, in get_result\n    raise exc.with_traceback(exc.__traceback__)\n  File \"/home/ubuntu/actions-runner/_work/sdcore-tests/sdcore-tests/.tox/integration/lib/python3.10/site-packages/pluggy/_callers.py\", line 167, in _multicall\n    teardown.throw(outcome._exception)\n  File \"/home/ubuntu/actions-runner/_work/sdcore-tests/sdcore-tests/.tox/integration/lib/python3.10/site-packages/_pytest/threadexception.py\", line 92, in pytest_runtest_call\n    yield from thread_exception_runtest_hook()\n  File \"/home/ubuntu/actions-runner/_work/sdcore-tests/sdcore-tests/.tox/integration/lib/python3.10/site-packages/_pytest/threadexception.py\", line 68, in thread_exception_runtest_hook\n    yield\n  File \"/home/ubuntu/actions-runner/_work/sdcore-tests/sdcore-tests/.tox/integration/lib/python3.10/site-packages/pluggy/_callers.py\", line 167, in _multicall\n    teardown.throw(outcome._exception)\n  File \"/home/ubuntu/actions-runner/_work/sdcore-tests/sdcore-tests/.tox/integration/lib/python3.10/site-packages/_pytest/unraisableexception.py\", line 95, in pytest_runtest_call\n    yield from unraisable_exception_runtest_hook()\n  File \"/home/ubuntu/actions-runner/_work/sdcore-tests/sdcore-tests/.tox/integration/lib/python3.10/site-packages/_pytest/unraisableexception.py\", line 70, in unraisable_exception_runtest_hook\n    yield\n  File \"/home/ubuntu/actions-runner/_work/sdcore-tests/sdcore-tests/.tox/integration/lib/python3.10/site-packages/pluggy/_callers.py\", line 167, in _multicall\n    teardown.throw(outcome._exception)\n  File \"/home/ubuntu/actions-runner/_work/sdcore-tests/sdcore-tests/.tox/integration/lib/python3.10/site-packages/_pytest/logging.py\", line 846, in pytest_runtest_call\n    yield from self._runtest_for(item, \"call\")\n  File \"/home/ubuntu/actions-runner/_work/sdcore-tests/sdcore-tests/.tox/integration/lib/python3.10/site-packages/_pytest/logging.py\", line 829, in _runtest_for\n    yield\n  File \"/home/ubuntu/actions-runner/_work/sdcore-tests/sdcore-tests/.tox/integration/lib/python3.10/site-packages/pluggy/_callers.py\", line 167, in _multicall\n    teardown.throw(outcome._exception)\n  File \"/home/ubuntu/actions-runner/_work/sdcore-tests/sdcore-tests/.tox/integration/lib/python3.10/site-packages/_pytest/capture.py\", line 880, in pytest_runtest_call\n    return (yield)\n  File \"/home/ubuntu/actions-runner/_work/sdcore-tests/sdcore-tests/.tox/integration/lib/python3.10/site-packages/pluggy/_callers.py\", line 167, in _multicall\n    teardown.throw(outcome._exception)\n  File \"/home/ubuntu/actions-runner/_work/sdcore-tests/sdcore-tests/.tox/integration/lib/python3.10/site-packages/_pytest/skipping.py\", line 257, in pytest_runtest_call\n    return (yield)\n  File \"/home/ubuntu/actions-runner/_work/sdcore-tests/sdcore-tests/.tox/integration/lib/python3.10/site-packages/pluggy/_callers.py\", line 103, in _multicall\n    res = hook_impl.function(*args)\n  File \"/home/ubuntu/actions-runner/_work/sdcore-tests/sdcore-tests/.tox/integration/lib/python3.10/site-packages/_pytest/runner.py\", line 174, in pytest_runtest_call\n    item.runtest()\n  File \"/home/ubuntu/actions-runner/_work/sdcore-tests/sdcore-tests/.tox/integration/lib/python3.10/site-packages/_pytest/python.py\", line 1627, in runtest\n    self.ihook.pytest_pyfunc_call(pyfuncitem=self)\n  File \"/home/ubuntu/actions-runner/_work/sdcore-tests/sdcore-tests/.tox/integration/lib/python3.10/site-packages/pluggy/_hooks.py\", line 513, in __call__\n    return self._hookexec(self.name, self._hookimpls.copy(), kwargs, firstresult)\n  File \"/home/ubuntu/actions-runner/_work/sdcore-tests/sdcore-tests/.tox/integration/lib/python3.10/site-packages/pluggy/_manager.py\", line 120, in _hookexec\n    return self._inner_hookexec(hook_name, methods, kwargs, firstresult)\n  File \"/home/ubuntu/actions-runner/_work/sdcore-tests/sdcore-tests/.tox/integration/lib/python3.10/site-packages/pluggy/_callers.py\", line 182, in _multicall\n    return outcome.get_result()\n  File \"/home/ubuntu/actions-runner/_work/sdcore-tests/sdcore-tests/.tox/integration/lib/python3.10/site-packages/pluggy/_result.py\", line 100, in get_result\n    raise exc.with_traceback(exc.__traceback__)\n  File \"/home/ubuntu/actions-runner/_work/sdcore-tests/sdcore-tests/.tox/integration/lib/python3.10/site-packages/pluggy/_callers.py\", line 103, in _multicall\n    res = hook_impl.function(*args)\n  File \"/home/ubuntu/actions-runner/_work/sdcore-tests/sdcore-tests/.tox/integration/lib/python3.10/site-packages/_pytest/python.py\", line 159, in pytest_pyfunc_call\n    result = testfunction(**testargs)\n  File \"/home/ubuntu/actions-runner/_work/sdcore-tests/sdcore-tests/.tox/integration/lib/python3.10/site-packages/pytest_asyncio/plugin.py\", line 529, in inner\n    _loop.run_until_complete(task)\n  File \"/usr/lib/python3.10/asyncio/base_events.py\", line 649, in run_until_complete\n    return future.result()\n  File \"/home/ubuntu/actions-runner/_work/sdcore-tests/sdcore-tests/tests/integration/test_integration.py\", line 43, in test_given_sdcore_terraform_module_when_deploy_then_status_is_active\n    self._deploy_sdcore()\n  File \"/home/ubuntu/actions-runner/_work/sdcore-tests/sdcore-tests/tests/integration/test_integration.py\", line 105, in _deploy_sdcore\n    tf_client.apply()\n  File \"/home/ubuntu/actions-runner/_work/sdcore-tests/sdcore-tests/tests/integration/terraform_helper.py\", line 76, in apply\n    raise TerraformError(\ntests.integration.terraform_helper.TerraformError: Error running `terraform apply`","flaky":false,"newFailed":false,"newBroken":false,"newPassed":false,"retriesCount":0,"retriesStatusChange":false,"beforeStages":[{"name":"event_loop","time":{"start":1740277740829,"stop":1740277740830,"duration":1},"status":"passed","steps":[],"attachments":[],"parameters":[],"shouldDisplayMessage":false,"stepsCount":0,"attachmentsCount":0,"hasContent":false,"attachmentStep":false},{"name":"_xunit_setup_class_fixture_TestSDCoreBundle","time":{"start":1740277740830,"stop":1740277741189,"duration":359},"status":"passed","steps":[],"attachments":[],"parameters":[],"shouldDisplayMessage":false,"stepsCount":0,"attachmentsCount":0,"hasContent":false,"attachmentStep":false},{"name":"abort_on_fail","time":{"start":1740277741189,"stop":1740277741189,"duration":0},"status":"passed","steps":[],"attachments":[],"parameters":[],"shouldDisplayMessage":false,"stepsCount":0,"attachmentsCount":0,"hasContent":false,"attachmentStep":false}],"testStage":{"status":"broken","statusMessage":"tests.integration.terraform_helper.TerraformError: Error running `terraform apply`","statusTrace":"Traceback (most recent call last):\n  File \"/home/ubuntu/actions-runner/_work/sdcore-tests/sdcore-tests/tests/integration/terraform_helper.py\", line 74, in apply\n    self._run_terraform_cmd(TerraformCommands.apply, *args)\n  File \"/home/ubuntu/actions-runner/_work/sdcore-tests/sdcore-tests/tests/integration/terraform_helper.py\", line 100, in _run_terraform_cmd\n    return check_call([TERRAFORM_APP_NAME, terraform_command, *args], cwd=self.work_dir)\n  File \"/usr/lib/python3.10/subprocess.py\", line 369, in check_call\n    raise CalledProcessError(retcode, cmd)\nsubprocess.CalledProcessError: Command '['terraform', <TerraformCommands.apply: 'apply'>, '-auto-approve']' returned non-zero exit status 1.\n\nThe above exception was the direct cause of the following exception:\n\nTraceback (most recent call last):\n  File \"/home/ubuntu/actions-runner/_work/sdcore-tests/sdcore-tests/.tox/integration/lib/python3.10/site-packages/_pytest/runner.py\", line 341, in from_call\n    result: TResult | None = func()\n  File \"/home/ubuntu/actions-runner/_work/sdcore-tests/sdcore-tests/.tox/integration/lib/python3.10/site-packages/_pytest/runner.py\", line 242, in <lambda>\n    lambda: runtest_hook(item=item, **kwds), when=when, reraise=reraise\n  File \"/home/ubuntu/actions-runner/_work/sdcore-tests/sdcore-tests/.tox/integration/lib/python3.10/site-packages/pluggy/_hooks.py\", line 513, in __call__\n    return self._hookexec(self.name, self._hookimpls.copy(), kwargs, firstresult)\n  File \"/home/ubuntu/actions-runner/_work/sdcore-tests/sdcore-tests/.tox/integration/lib/python3.10/site-packages/pluggy/_manager.py\", line 120, in _hookexec\n    return self._inner_hookexec(hook_name, methods, kwargs, firstresult)\n  File \"/home/ubuntu/actions-runner/_work/sdcore-tests/sdcore-tests/.tox/integration/lib/python3.10/site-packages/pluggy/_callers.py\", line 182, in _multicall\n    return outcome.get_result()\n  File \"/home/ubuntu/actions-runner/_work/sdcore-tests/sdcore-tests/.tox/integration/lib/python3.10/site-packages/pluggy/_result.py\", line 100, in get_result\n    raise exc.with_traceback(exc.__traceback__)\n  File \"/home/ubuntu/actions-runner/_work/sdcore-tests/sdcore-tests/.tox/integration/lib/python3.10/site-packages/pluggy/_callers.py\", line 167, in _multicall\n    teardown.throw(outcome._exception)\n  File \"/home/ubuntu/actions-runner/_work/sdcore-tests/sdcore-tests/.tox/integration/lib/python3.10/site-packages/_pytest/threadexception.py\", line 92, in pytest_runtest_call\n    yield from thread_exception_runtest_hook()\n  File \"/home/ubuntu/actions-runner/_work/sdcore-tests/sdcore-tests/.tox/integration/lib/python3.10/site-packages/_pytest/threadexception.py\", line 68, in thread_exception_runtest_hook\n    yield\n  File \"/home/ubuntu/actions-runner/_work/sdcore-tests/sdcore-tests/.tox/integration/lib/python3.10/site-packages/pluggy/_callers.py\", line 167, in _multicall\n    teardown.throw(outcome._exception)\n  File \"/home/ubuntu/actions-runner/_work/sdcore-tests/sdcore-tests/.tox/integration/lib/python3.10/site-packages/_pytest/unraisableexception.py\", line 95, in pytest_runtest_call\n    yield from unraisable_exception_runtest_hook()\n  File \"/home/ubuntu/actions-runner/_work/sdcore-tests/sdcore-tests/.tox/integration/lib/python3.10/site-packages/_pytest/unraisableexception.py\", line 70, in unraisable_exception_runtest_hook\n    yield\n  File \"/home/ubuntu/actions-runner/_work/sdcore-tests/sdcore-tests/.tox/integration/lib/python3.10/site-packages/pluggy/_callers.py\", line 167, in _multicall\n    teardown.throw(outcome._exception)\n  File \"/home/ubuntu/actions-runner/_work/sdcore-tests/sdcore-tests/.tox/integration/lib/python3.10/site-packages/_pytest/logging.py\", line 846, in pytest_runtest_call\n    yield from self._runtest_for(item, \"call\")\n  File \"/home/ubuntu/actions-runner/_work/sdcore-tests/sdcore-tests/.tox/integration/lib/python3.10/site-packages/_pytest/logging.py\", line 829, in _runtest_for\n    yield\n  File \"/home/ubuntu/actions-runner/_work/sdcore-tests/sdcore-tests/.tox/integration/lib/python3.10/site-packages/pluggy/_callers.py\", line 167, in _multicall\n    teardown.throw(outcome._exception)\n  File \"/home/ubuntu/actions-runner/_work/sdcore-tests/sdcore-tests/.tox/integration/lib/python3.10/site-packages/_pytest/capture.py\", line 880, in pytest_runtest_call\n    return (yield)\n  File \"/home/ubuntu/actions-runner/_work/sdcore-tests/sdcore-tests/.tox/integration/lib/python3.10/site-packages/pluggy/_callers.py\", line 167, in _multicall\n    teardown.throw(outcome._exception)\n  File \"/home/ubuntu/actions-runner/_work/sdcore-tests/sdcore-tests/.tox/integration/lib/python3.10/site-packages/_pytest/skipping.py\", line 257, in pytest_runtest_call\n    return (yield)\n  File \"/home/ubuntu/actions-runner/_work/sdcore-tests/sdcore-tests/.tox/integration/lib/python3.10/site-packages/pluggy/_callers.py\", line 103, in _multicall\n    res = hook_impl.function(*args)\n  File \"/home/ubuntu/actions-runner/_work/sdcore-tests/sdcore-tests/.tox/integration/lib/python3.10/site-packages/_pytest/runner.py\", line 174, in pytest_runtest_call\n    item.runtest()\n  File \"/home/ubuntu/actions-runner/_work/sdcore-tests/sdcore-tests/.tox/integration/lib/python3.10/site-packages/_pytest/python.py\", line 1627, in runtest\n    self.ihook.pytest_pyfunc_call(pyfuncitem=self)\n  File \"/home/ubuntu/actions-runner/_work/sdcore-tests/sdcore-tests/.tox/integration/lib/python3.10/site-packages/pluggy/_hooks.py\", line 513, in __call__\n    return self._hookexec(self.name, self._hookimpls.copy(), kwargs, firstresult)\n  File \"/home/ubuntu/actions-runner/_work/sdcore-tests/sdcore-tests/.tox/integration/lib/python3.10/site-packages/pluggy/_manager.py\", line 120, in _hookexec\n    return self._inner_hookexec(hook_name, methods, kwargs, firstresult)\n  File \"/home/ubuntu/actions-runner/_work/sdcore-tests/sdcore-tests/.tox/integration/lib/python3.10/site-packages/pluggy/_callers.py\", line 182, in _multicall\n    return outcome.get_result()\n  File \"/home/ubuntu/actions-runner/_work/sdcore-tests/sdcore-tests/.tox/integration/lib/python3.10/site-packages/pluggy/_result.py\", line 100, in get_result\n    raise exc.with_traceback(exc.__traceback__)\n  File \"/home/ubuntu/actions-runner/_work/sdcore-tests/sdcore-tests/.tox/integration/lib/python3.10/site-packages/pluggy/_callers.py\", line 103, in _multicall\n    res = hook_impl.function(*args)\n  File \"/home/ubuntu/actions-runner/_work/sdcore-tests/sdcore-tests/.tox/integration/lib/python3.10/site-packages/_pytest/python.py\", line 159, in pytest_pyfunc_call\n    result = testfunction(**testargs)\n  File \"/home/ubuntu/actions-runner/_work/sdcore-tests/sdcore-tests/.tox/integration/lib/python3.10/site-packages/pytest_asyncio/plugin.py\", line 529, in inner\n    _loop.run_until_complete(task)\n  File \"/usr/lib/python3.10/asyncio/base_events.py\", line 649, in run_until_complete\n    return future.result()\n  File \"/home/ubuntu/actions-runner/_work/sdcore-tests/sdcore-tests/tests/integration/test_integration.py\", line 43, in test_given_sdcore_terraform_module_when_deploy_then_status_is_active\n    self._deploy_sdcore()\n  File \"/home/ubuntu/actions-runner/_work/sdcore-tests/sdcore-tests/tests/integration/test_integration.py\", line 105, in _deploy_sdcore\n    tf_client.apply()\n  File \"/home/ubuntu/actions-runner/_work/sdcore-tests/sdcore-tests/tests/integration/terraform_helper.py\", line 76, in apply\n    raise TerraformError(\ntests.integration.terraform_helper.TerraformError: Error running `terraform apply`","steps":[],"attachments":[{"uid":"537f5fd4bb0fb3dd","name":"log","source":"537f5fd4bb0fb3dd.txt","type":"text/plain","size":563}],"parameters":[],"shouldDisplayMessage":true,"stepsCount":0,"attachmentsCount":1,"hasContent":true,"attachmentStep":false},"afterStages":[{"name":"abort_on_fail::0","time":{"start":1740278047966,"stop":1740278047966,"duration":0},"status":"passed","steps":[],"attachments":[],"parameters":[],"shouldDisplayMessage":false,"stepsCount":0,"attachmentsCount":0,"hasContent":false,"attachmentStep":false},{"name":"_xunit_setup_class_fixture_TestSDCoreBundle::0","time":{"start":1740278132089,"stop":1740278132089,"duration":0},"status":"passed","steps":[],"attachments":[],"parameters":[],"shouldDisplayMessage":false,"stepsCount":0,"attachmentsCount":0,"hasContent":false,"attachmentStep":false},{"name":"event_loop::2","time":{"start":1740278132089,"stop":1740278132089,"duration":0},"status":"passed","steps":[],"attachments":[],"parameters":[],"shouldDisplayMessage":false,"stepsCount":0,"attachmentsCount":0,"hasContent":false,"attachmentStep":false},{"name":"event_loop::_close_event_loop","time":{"start":1740278132089,"stop":1740278132089,"duration":0},"status":"passed","steps":[],"attachments":[],"parameters":[],"shouldDisplayMessage":false,"stepsCount":0,"attachmentsCount":0,"hasContent":false,"attachmentStep":false},{"name":"event_loop::_provide_clean_event_loop","time":{"start":1740278132089,"stop":1740278132089,"duration":0},"status":"passed","steps":[],"attachments":[],"parameters":[],"shouldDisplayMessage":false,"stepsCount":0,"attachmentsCount":0,"hasContent":false,"attachmentStep":false}],"labels":[{"name":"tag","value":"abort_on_fail"},{"name":"tag","value":"asyncio"},{"name":"parentSuite","value":"tests.integration"},{"name":"suite","value":"test_integration"},{"name":"subSuite","value":"TestSDCoreBundle"},{"name":"host","value":"github-runner"},{"name":"thread","value":"22125-MainThread"},{"name":"framework","value":"pytest"},{"name":"language","value":"cpython3"},{"name":"package","value":"tests.integration.test_integration"},{"name":"resultFormat","value":"allure2"}],"parameters":[],"links":[],"hidden":false,"retry":false,"extra":{"severity":"normal","retries":[],"categories":[{"name":"Test defects","matchedStatuses":[],"flaky":false}],"tags":["asyncio","abort_on_fail"]},"source":"388113e9603970f6.json","parameterValues":[]}