{"uid":"4785521ea9c2e549","name":"test_given_sdcore_terraform_module_when_deploy_then_status_is_active","fullName":"tests.integration.test_integration.TestSDCoreBundle#test_given_sdcore_terraform_module_when_deploy_then_status_is_active","historyId":"5abf18a073330975d0499b6d3bc096cd","time":{"start":1741159647239,"stop":1741159686156,"duration":38917},"status":"broken","statusMessage":"tests.integration.terraform_helper.TerraformError: Error running `terraform apply`","statusTrace":"Traceback (most recent call last):\n  File \"/home/ubuntu/actions-runner/_work/sdcore-tests/sdcore-tests/tests/integration/terraform_helper.py\", line 74, in apply\n    self._run_terraform_cmd(TerraformCommands.apply, *args)\n  File \"/home/ubuntu/actions-runner/_work/sdcore-tests/sdcore-tests/tests/integration/terraform_helper.py\", line 100, in _run_terraform_cmd\n    return check_call([TERRAFORM_APP_NAME, terraform_command, *args], cwd=self.work_dir)\n  File \"/usr/lib/python3.10/subprocess.py\", line 369, in check_call\n    raise CalledProcessError(retcode, cmd)\nsubprocess.CalledProcessError: Command '['terraform', <TerraformCommands.apply: 'apply'>, '-auto-approve']' returned non-zero exit status 1.\n\nThe above exception was the direct cause of the following exception:\n\nTraceback (most recent call last):\n  File \"/home/ubuntu/actions-runner/_work/sdcore-tests/sdcore-tests/.tox/integration/lib/python3.10/site-packages/_pytest/runner.py\", line 341, in from_call\n    result: TResult | None = func()\n  File \"/home/ubuntu/actions-runner/_work/sdcore-tests/sdcore-tests/.tox/integration/lib/python3.10/site-packages/_pytest/runner.py\", line 242, in <lambda>\n    lambda: runtest_hook(item=item, **kwds), when=when, reraise=reraise\n  File \"/home/ubuntu/actions-runner/_work/sdcore-tests/sdcore-tests/.tox/integration/lib/python3.10/site-packages/pluggy/_hooks.py\", line 513, in __call__\n    return self._hookexec(self.name, self._hookimpls.copy(), kwargs, firstresult)\n  File \"/home/ubuntu/actions-runner/_work/sdcore-tests/sdcore-tests/.tox/integration/lib/python3.10/site-packages/pluggy/_manager.py\", line 120, in _hookexec\n    return self._inner_hookexec(hook_name, methods, kwargs, firstresult)\n  File \"/home/ubuntu/actions-runner/_work/sdcore-tests/sdcore-tests/.tox/integration/lib/python3.10/site-packages/pluggy/_callers.py\", line 182, in _multicall\n    return outcome.get_result()\n  File \"/home/ubuntu/actions-runner/_work/sdcore-tests/sdcore-tests/.tox/integration/lib/python3.10/site-packages/pluggy/_result.py\", line 100, in get_result\n    raise exc.with_traceback(exc.__traceback__)\n  File \"/home/ubuntu/actions-runner/_work/sdcore-tests/sdcore-tests/.tox/integration/lib/python3.10/site-packages/pluggy/_callers.py\", line 167, in _multicall\n    teardown.throw(outcome._exception)\n  File \"/home/ubuntu/actions-runner/_work/sdcore-tests/sdcore-tests/.tox/integration/lib/python3.10/site-packages/_pytest/threadexception.py\", line 92, in pytest_runtest_call\n    yield from thread_exception_runtest_hook()\n  File \"/home/ubuntu/actions-runner/_work/sdcore-tests/sdcore-tests/.tox/integration/lib/python3.10/site-packages/_pytest/threadexception.py\", line 68, in thread_exception_runtest_hook\n    yield\n  File \"/home/ubuntu/actions-runner/_work/sdcore-tests/sdcore-tests/.tox/integration/lib/python3.10/site-packages/pluggy/_callers.py\", line 167, in _multicall\n    teardown.throw(outcome._exception)\n  File \"/home/ubuntu/actions-runner/_work/sdcore-tests/sdcore-tests/.tox/integration/lib/python3.10/site-packages/_pytest/unraisableexception.py\", line 95, in pytest_runtest_call\n    yield from unraisable_exception_runtest_hook()\n  File \"/home/ubuntu/actions-runner/_work/sdcore-tests/sdcore-tests/.tox/integration/lib/python3.10/site-packages/_pytest/unraisableexception.py\", line 70, in unraisable_exception_runtest_hook\n    yield\n  File \"/home/ubuntu/actions-runner/_work/sdcore-tests/sdcore-tests/.tox/integration/lib/python3.10/site-packages/pluggy/_callers.py\", line 167, in _multicall\n    teardown.throw(outcome._exception)\n  File \"/home/ubuntu/actions-runner/_work/sdcore-tests/sdcore-tests/.tox/integration/lib/python3.10/site-packages/_pytest/logging.py\", line 846, in pytest_runtest_call\n    yield from self._runtest_for(item, \"call\")\n  File \"/home/ubuntu/actions-runner/_work/sdcore-tests/sdcore-tests/.tox/integration/lib/python3.10/site-packages/_pytest/logging.py\", line 829, in _runtest_for\n    yield\n  File \"/home/ubuntu/actions-runner/_work/sdcore-tests/sdcore-tests/.tox/integration/lib/python3.10/site-packages/pluggy/_callers.py\", line 167, in _multicall\n    teardown.throw(outcome._exception)\n  File \"/home/ubuntu/actions-runner/_work/sdcore-tests/sdcore-tests/.tox/integration/lib/python3.10/site-packages/_pytest/capture.py\", line 880, in pytest_runtest_call\n    return (yield)\n  File \"/home/ubuntu/actions-runner/_work/sdcore-tests/sdcore-tests/.tox/integration/lib/python3.10/site-packages/pluggy/_callers.py\", line 167, in _multicall\n    teardown.throw(outcome._exception)\n  File \"/home/ubuntu/actions-runner/_work/sdcore-tests/sdcore-tests/.tox/integration/lib/python3.10/site-packages/_pytest/skipping.py\", line 257, in pytest_runtest_call\n    return (yield)\n  File \"/home/ubuntu/actions-runner/_work/sdcore-tests/sdcore-tests/.tox/integration/lib/python3.10/site-packages/pluggy/_callers.py\", line 103, in _multicall\n    res = hook_impl.function(*args)\n  File \"/home/ubuntu/actions-runner/_work/sdcore-tests/sdcore-tests/.tox/integration/lib/python3.10/site-packages/_pytest/runner.py\", line 174, in pytest_runtest_call\n    item.runtest()\n  File \"/home/ubuntu/actions-runner/_work/sdcore-tests/sdcore-tests/.tox/integration/lib/python3.10/site-packages/_pytest/python.py\", line 1627, in runtest\n    self.ihook.pytest_pyfunc_call(pyfuncitem=self)\n  File \"/home/ubuntu/actions-runner/_work/sdcore-tests/sdcore-tests/.tox/integration/lib/python3.10/site-packages/pluggy/_hooks.py\", line 513, in __call__\n    return self._hookexec(self.name, self._hookimpls.copy(), kwargs, firstresult)\n  File \"/home/ubuntu/actions-runner/_work/sdcore-tests/sdcore-tests/.tox/integration/lib/python3.10/site-packages/pluggy/_manager.py\", line 120, in _hookexec\n    return self._inner_hookexec(hook_name, methods, kwargs, firstresult)\n  File \"/home/ubuntu/actions-runner/_work/sdcore-tests/sdcore-tests/.tox/integration/lib/python3.10/site-packages/pluggy/_callers.py\", line 182, in _multicall\n    return outcome.get_result()\n  File \"/home/ubuntu/actions-runner/_work/sdcore-tests/sdcore-tests/.tox/integration/lib/python3.10/site-packages/pluggy/_result.py\", line 100, in get_result\n    raise exc.with_traceback(exc.__traceback__)\n  File \"/home/ubuntu/actions-runner/_work/sdcore-tests/sdcore-tests/.tox/integration/lib/python3.10/site-packages/pluggy/_callers.py\", line 103, in _multicall\n    res = hook_impl.function(*args)\n  File \"/home/ubuntu/actions-runner/_work/sdcore-tests/sdcore-tests/.tox/integration/lib/python3.10/site-packages/_pytest/python.py\", line 159, in pytest_pyfunc_call\n    result = testfunction(**testargs)\n  File \"/home/ubuntu/actions-runner/_work/sdcore-tests/sdcore-tests/.tox/integration/lib/python3.10/site-packages/pytest_asyncio/plugin.py\", line 529, in inner\n    _loop.run_until_complete(task)\n  File \"/usr/lib/python3.10/asyncio/base_events.py\", line 649, in run_until_complete\n    return future.result()\n  File \"/home/ubuntu/actions-runner/_work/sdcore-tests/sdcore-tests/tests/integration/test_integration.py\", line 43, in test_given_sdcore_terraform_module_when_deploy_then_status_is_active\n    self._deploy_sdcore()\n  File \"/home/ubuntu/actions-runner/_work/sdcore-tests/sdcore-tests/tests/integration/test_integration.py\", line 108, in _deploy_sdcore\n    tf_client.apply()\n  File \"/home/ubuntu/actions-runner/_work/sdcore-tests/sdcore-tests/tests/integration/terraform_helper.py\", line 76, in apply\n    raise TerraformError(\ntests.integration.terraform_helper.TerraformError: Error running `terraform apply`","flaky":false,"newFailed":false,"newBroken":false,"newPassed":false,"retriesCount":0,"retriesStatusChange":false,"beforeStages":[{"name":"event_loop","time":{"start":1741159646718,"stop":1741159646719,"duration":1},"status":"passed","steps":[],"attachments":[],"parameters":[],"shouldDisplayMessage":false,"stepsCount":0,"attachmentsCount":0,"hasContent":false,"attachmentStep":false},{"name":"_xunit_setup_class_fixture_TestSDCoreBundle","time":{"start":1741159646719,"stop":1741159647238,"duration":519},"status":"passed","steps":[],"attachments":[],"parameters":[],"shouldDisplayMessage":false,"stepsCount":0,"attachmentsCount":0,"hasContent":false,"attachmentStep":false},{"name":"abort_on_fail","time":{"start":1741159647239,"stop":1741159647239,"duration":0},"status":"passed","steps":[],"attachments":[],"parameters":[],"shouldDisplayMessage":false,"stepsCount":0,"attachmentsCount":0,"hasContent":false,"attachmentStep":false}],"testStage":{"status":"broken","statusMessage":"tests.integration.terraform_helper.TerraformError: Error running `terraform apply`","statusTrace":"Traceback (most recent call last):\n  File \"/home/ubuntu/actions-runner/_work/sdcore-tests/sdcore-tests/tests/integration/terraform_helper.py\", line 74, in apply\n    self._run_terraform_cmd(TerraformCommands.apply, *args)\n  File \"/home/ubuntu/actions-runner/_work/sdcore-tests/sdcore-tests/tests/integration/terraform_helper.py\", line 100, in _run_terraform_cmd\n    return check_call([TERRAFORM_APP_NAME, terraform_command, *args], cwd=self.work_dir)\n  File \"/usr/lib/python3.10/subprocess.py\", line 369, in check_call\n    raise CalledProcessError(retcode, cmd)\nsubprocess.CalledProcessError: Command '['terraform', <TerraformCommands.apply: 'apply'>, '-auto-approve']' returned non-zero exit status 1.\n\nThe above exception was the direct cause of the following exception:\n\nTraceback (most recent call last):\n  File \"/home/ubuntu/actions-runner/_work/sdcore-tests/sdcore-tests/.tox/integration/lib/python3.10/site-packages/_pytest/runner.py\", line 341, in from_call\n    result: TResult | None = func()\n  File \"/home/ubuntu/actions-runner/_work/sdcore-tests/sdcore-tests/.tox/integration/lib/python3.10/site-packages/_pytest/runner.py\", line 242, in <lambda>\n    lambda: runtest_hook(item=item, **kwds), when=when, reraise=reraise\n  File \"/home/ubuntu/actions-runner/_work/sdcore-tests/sdcore-tests/.tox/integration/lib/python3.10/site-packages/pluggy/_hooks.py\", line 513, in __call__\n    return self._hookexec(self.name, self._hookimpls.copy(), kwargs, firstresult)\n  File \"/home/ubuntu/actions-runner/_work/sdcore-tests/sdcore-tests/.tox/integration/lib/python3.10/site-packages/pluggy/_manager.py\", line 120, in _hookexec\n    return self._inner_hookexec(hook_name, methods, kwargs, firstresult)\n  File \"/home/ubuntu/actions-runner/_work/sdcore-tests/sdcore-tests/.tox/integration/lib/python3.10/site-packages/pluggy/_callers.py\", line 182, in _multicall\n    return outcome.get_result()\n  File \"/home/ubuntu/actions-runner/_work/sdcore-tests/sdcore-tests/.tox/integration/lib/python3.10/site-packages/pluggy/_result.py\", line 100, in get_result\n    raise exc.with_traceback(exc.__traceback__)\n  File \"/home/ubuntu/actions-runner/_work/sdcore-tests/sdcore-tests/.tox/integration/lib/python3.10/site-packages/pluggy/_callers.py\", line 167, in _multicall\n    teardown.throw(outcome._exception)\n  File \"/home/ubuntu/actions-runner/_work/sdcore-tests/sdcore-tests/.tox/integration/lib/python3.10/site-packages/_pytest/threadexception.py\", line 92, in pytest_runtest_call\n    yield from thread_exception_runtest_hook()\n  File \"/home/ubuntu/actions-runner/_work/sdcore-tests/sdcore-tests/.tox/integration/lib/python3.10/site-packages/_pytest/threadexception.py\", line 68, in thread_exception_runtest_hook\n    yield\n  File \"/home/ubuntu/actions-runner/_work/sdcore-tests/sdcore-tests/.tox/integration/lib/python3.10/site-packages/pluggy/_callers.py\", line 167, in _multicall\n    teardown.throw(outcome._exception)\n  File \"/home/ubuntu/actions-runner/_work/sdcore-tests/sdcore-tests/.tox/integration/lib/python3.10/site-packages/_pytest/unraisableexception.py\", line 95, in pytest_runtest_call\n    yield from unraisable_exception_runtest_hook()\n  File \"/home/ubuntu/actions-runner/_work/sdcore-tests/sdcore-tests/.tox/integration/lib/python3.10/site-packages/_pytest/unraisableexception.py\", line 70, in unraisable_exception_runtest_hook\n    yield\n  File \"/home/ubuntu/actions-runner/_work/sdcore-tests/sdcore-tests/.tox/integration/lib/python3.10/site-packages/pluggy/_callers.py\", line 167, in _multicall\n    teardown.throw(outcome._exception)\n  File \"/home/ubuntu/actions-runner/_work/sdcore-tests/sdcore-tests/.tox/integration/lib/python3.10/site-packages/_pytest/logging.py\", line 846, in pytest_runtest_call\n    yield from self._runtest_for(item, \"call\")\n  File \"/home/ubuntu/actions-runner/_work/sdcore-tests/sdcore-tests/.tox/integration/lib/python3.10/site-packages/_pytest/logging.py\", line 829, in _runtest_for\n    yield\n  File \"/home/ubuntu/actions-runner/_work/sdcore-tests/sdcore-tests/.tox/integration/lib/python3.10/site-packages/pluggy/_callers.py\", line 167, in _multicall\n    teardown.throw(outcome._exception)\n  File \"/home/ubuntu/actions-runner/_work/sdcore-tests/sdcore-tests/.tox/integration/lib/python3.10/site-packages/_pytest/capture.py\", line 880, in pytest_runtest_call\n    return (yield)\n  File \"/home/ubuntu/actions-runner/_work/sdcore-tests/sdcore-tests/.tox/integration/lib/python3.10/site-packages/pluggy/_callers.py\", line 167, in _multicall\n    teardown.throw(outcome._exception)\n  File \"/home/ubuntu/actions-runner/_work/sdcore-tests/sdcore-tests/.tox/integration/lib/python3.10/site-packages/_pytest/skipping.py\", line 257, in pytest_runtest_call\n    return (yield)\n  File \"/home/ubuntu/actions-runner/_work/sdcore-tests/sdcore-tests/.tox/integration/lib/python3.10/site-packages/pluggy/_callers.py\", line 103, in _multicall\n    res = hook_impl.function(*args)\n  File \"/home/ubuntu/actions-runner/_work/sdcore-tests/sdcore-tests/.tox/integration/lib/python3.10/site-packages/_pytest/runner.py\", line 174, in pytest_runtest_call\n    item.runtest()\n  File \"/home/ubuntu/actions-runner/_work/sdcore-tests/sdcore-tests/.tox/integration/lib/python3.10/site-packages/_pytest/python.py\", line 1627, in runtest\n    self.ihook.pytest_pyfunc_call(pyfuncitem=self)\n  File \"/home/ubuntu/actions-runner/_work/sdcore-tests/sdcore-tests/.tox/integration/lib/python3.10/site-packages/pluggy/_hooks.py\", line 513, in __call__\n    return self._hookexec(self.name, self._hookimpls.copy(), kwargs, firstresult)\n  File \"/home/ubuntu/actions-runner/_work/sdcore-tests/sdcore-tests/.tox/integration/lib/python3.10/site-packages/pluggy/_manager.py\", line 120, in _hookexec\n    return self._inner_hookexec(hook_name, methods, kwargs, firstresult)\n  File \"/home/ubuntu/actions-runner/_work/sdcore-tests/sdcore-tests/.tox/integration/lib/python3.10/site-packages/pluggy/_callers.py\", line 182, in _multicall\n    return outcome.get_result()\n  File \"/home/ubuntu/actions-runner/_work/sdcore-tests/sdcore-tests/.tox/integration/lib/python3.10/site-packages/pluggy/_result.py\", line 100, in get_result\n    raise exc.with_traceback(exc.__traceback__)\n  File \"/home/ubuntu/actions-runner/_work/sdcore-tests/sdcore-tests/.tox/integration/lib/python3.10/site-packages/pluggy/_callers.py\", line 103, in _multicall\n    res = hook_impl.function(*args)\n  File \"/home/ubuntu/actions-runner/_work/sdcore-tests/sdcore-tests/.tox/integration/lib/python3.10/site-packages/_pytest/python.py\", line 159, in pytest_pyfunc_call\n    result = testfunction(**testargs)\n  File \"/home/ubuntu/actions-runner/_work/sdcore-tests/sdcore-tests/.tox/integration/lib/python3.10/site-packages/pytest_asyncio/plugin.py\", line 529, in inner\n    _loop.run_until_complete(task)\n  File \"/usr/lib/python3.10/asyncio/base_events.py\", line 649, in run_until_complete\n    return future.result()\n  File \"/home/ubuntu/actions-runner/_work/sdcore-tests/sdcore-tests/tests/integration/test_integration.py\", line 43, in test_given_sdcore_terraform_module_when_deploy_then_status_is_active\n    self._deploy_sdcore()\n  File \"/home/ubuntu/actions-runner/_work/sdcore-tests/sdcore-tests/tests/integration/test_integration.py\", line 108, in _deploy_sdcore\n    tf_client.apply()\n  File \"/home/ubuntu/actions-runner/_work/sdcore-tests/sdcore-tests/tests/integration/terraform_helper.py\", line 76, in apply\n    raise TerraformError(\ntests.integration.terraform_helper.TerraformError: Error running `terraform apply`","steps":[],"attachments":[{"uid":"48ddce93762c522a","name":"log","source":"48ddce93762c522a.txt","type":"text/plain","size":563}],"parameters":[],"shouldDisplayMessage":true,"stepsCount":0,"attachmentsCount":1,"hasContent":true,"attachmentStep":false},"afterStages":[{"name":"abort_on_fail::0","time":{"start":1741159686161,"stop":1741159686161,"duration":0},"status":"passed","steps":[],"attachments":[],"parameters":[],"shouldDisplayMessage":false,"stepsCount":0,"attachmentsCount":0,"hasContent":false,"attachmentStep":false},{"name":"_xunit_setup_class_fixture_TestSDCoreBundle::0","time":{"start":1741159987231,"stop":1741159987231,"duration":0},"status":"passed","steps":[],"attachments":[],"parameters":[],"shouldDisplayMessage":false,"stepsCount":0,"attachmentsCount":0,"hasContent":false,"attachmentStep":false},{"name":"event_loop::2","time":{"start":1741159987231,"stop":1741159987232,"duration":1},"status":"passed","steps":[],"attachments":[],"parameters":[],"shouldDisplayMessage":false,"stepsCount":0,"attachmentsCount":0,"hasContent":false,"attachmentStep":false},{"name":"event_loop::_close_event_loop","time":{"start":1741159987232,"stop":1741159987232,"duration":0},"status":"passed","steps":[],"attachments":[],"parameters":[],"shouldDisplayMessage":false,"stepsCount":0,"attachmentsCount":0,"hasContent":false,"attachmentStep":false},{"name":"event_loop::_provide_clean_event_loop","time":{"start":1741159987232,"stop":1741159987232,"duration":0},"status":"passed","steps":[],"attachments":[],"parameters":[],"shouldDisplayMessage":false,"stepsCount":0,"attachmentsCount":0,"hasContent":false,"attachmentStep":false}],"labels":[{"name":"tag","value":"abort_on_fail"},{"name":"tag","value":"asyncio"},{"name":"parentSuite","value":"tests.integration"},{"name":"suite","value":"test_integration"},{"name":"subSuite","value":"TestSDCoreBundle"},{"name":"host","value":"github-runner"},{"name":"thread","value":"25244-MainThread"},{"name":"framework","value":"pytest"},{"name":"language","value":"cpython3"},{"name":"package","value":"tests.integration.test_integration"},{"name":"resultFormat","value":"allure2"}],"parameters":[],"links":[],"hidden":false,"retry":false,"extra":{"severity":"normal","retries":[],"categories":[{"name":"Test defects","matchedStatuses":[],"flaky":false}],"history":{"statistic":{"failed":0,"broken":4,"skipped":0,"passed":5,"unknown":0,"total":9},"items":[{"uid":"d8f1215ff2eb6fc2","reportUrl":"https://canonical.github.io/sdcore-tests/2313//#testresult/d8f1215ff2eb6fc2","status":"broken","statusDetails":"tests.integration.terraform_helper.TerraformError: Error running `terraform apply`","time":{"start":1741141731892,"stop":1741141766909,"duration":35017}},{"uid":"86485cd6460e5627","reportUrl":"https://canonical.github.io/sdcore-tests/2311//#testresult/86485cd6460e5627","status":"broken","statusDetails":"tests.integration.terraform_helper.TerraformError: Error running `terraform apply`","time":{"start":1741072178096,"stop":1741072439024,"duration":260928}},{"uid":"18b29f9e46f945fe","reportUrl":"https://canonical.github.io/sdcore-tests/2312//#testresult/18b29f9e46f945fe","status":"broken","statusDetails":"tests.integration.terraform_helper.TerraformError: Error running `terraform apply`","time":{"start":1741056047556,"stop":1741056344133,"duration":296577}},{"uid":"9abb20a4528902b3","reportUrl":"https://canonical.github.io/sdcore-tests/2311//#testresult/9abb20a4528902b3","status":"passed","time":{"start":1741018893880,"stop":1741019625165,"duration":731285}},{"uid":"5668c3057217539","reportUrl":"https://canonical.github.io/sdcore-tests/2308//#testresult/5668c3057217539","status":"passed","time":{"start":1740969077891,"stop":1740969471915,"duration":394024}},{"uid":"ed5d0cf6a27877c5","reportUrl":"https://canonical.github.io/sdcore-tests/2307//#testresult/ed5d0cf6a27877c5","status":"passed","time":{"start":1740882596065,"stop":1740882998457,"duration":402392}},{"uid":"a24171fba1383891","reportUrl":"https://canonical.github.io/sdcore-tests/2306//#testresult/a24171fba1383891","status":"passed","time":{"start":1740796244012,"stop":1740796651132,"duration":407120}},{"uid":"34bc3795cbffcaab","reportUrl":"https://canonical.github.io/sdcore-tests/2305//#testresult/34bc3795cbffcaab","status":"passed","time":{"start":1740746697909,"stop":1740747087907,"duration":389998}}]},"tags":["asyncio","abort_on_fail"]},"source":"4785521ea9c2e549.json","parameterValues":[]}