{"uid":"b7b3dfab69850c4e","name":"test_given_sdcore_terraform_module_when_deploy_then_status_is_active","fullName":"tests.integration.test_integration.TestSDCoreBundle#test_given_sdcore_terraform_module_when_deploy_then_status_is_active","historyId":"5abf18a073330975d0499b6d3bc096cd","time":{"start":1750473200993,"stop":1750473494784,"duration":293791},"status":"broken","statusMessage":"tests.integration.terraform_helper.TerraformError: Error running `terraform apply`","statusTrace":"Traceback (most recent call last):\n  File \"/home/ubuntu/actions-runner/_work/sdcore-tests/sdcore-tests/tests/integration/terraform_helper.py\", line 74, in apply\n    self._run_terraform_cmd(TerraformCommands.apply, *args)\n  File \"/home/ubuntu/actions-runner/_work/sdcore-tests/sdcore-tests/tests/integration/terraform_helper.py\", line 100, in _run_terraform_cmd\n    return check_call([TERRAFORM_APP_NAME, terraform_command, *args], cwd=self.work_dir)\n  File \"/usr/lib/python3.10/subprocess.py\", line 369, in check_call\n    raise CalledProcessError(retcode, cmd)\nsubprocess.CalledProcessError: Command '['terraform', <TerraformCommands.apply: 'apply'>, '-auto-approve']' returned non-zero exit status 1.\n\nThe above exception was the direct cause of the following exception:\n\nTraceback (most recent call last):\n  File \"/home/ubuntu/actions-runner/_work/sdcore-tests/sdcore-tests/.tox/integration/lib/python3.10/site-packages/_pytest/runner.py\", line 344, in from_call\n    result: TResult | None = func()\n  File \"/home/ubuntu/actions-runner/_work/sdcore-tests/sdcore-tests/.tox/integration/lib/python3.10/site-packages/_pytest/runner.py\", line 246, in <lambda>\n    lambda: runtest_hook(item=item, **kwds), when=when, reraise=reraise\n  File \"/home/ubuntu/actions-runner/_work/sdcore-tests/sdcore-tests/.tox/integration/lib/python3.10/site-packages/pluggy/_hooks.py\", line 512, in __call__\n    return self._hookexec(self.name, self._hookimpls.copy(), kwargs, firstresult)\n  File \"/home/ubuntu/actions-runner/_work/sdcore-tests/sdcore-tests/.tox/integration/lib/python3.10/site-packages/pluggy/_manager.py\", line 120, in _hookexec\n    return self._inner_hookexec(hook_name, methods, kwargs, firstresult)\n  File \"/home/ubuntu/actions-runner/_work/sdcore-tests/sdcore-tests/.tox/integration/lib/python3.10/site-packages/pluggy/_callers.py\", line 167, in _multicall\n    raise exception\n  File \"/home/ubuntu/actions-runner/_work/sdcore-tests/sdcore-tests/.tox/integration/lib/python3.10/site-packages/pluggy/_callers.py\", line 139, in _multicall\n    teardown.throw(exception)\n  File \"/home/ubuntu/actions-runner/_work/sdcore-tests/sdcore-tests/.tox/integration/lib/python3.10/site-packages/_pytest/logging.py\", line 850, in pytest_runtest_call\n    yield\n  File \"/home/ubuntu/actions-runner/_work/sdcore-tests/sdcore-tests/.tox/integration/lib/python3.10/site-packages/pluggy/_callers.py\", line 139, in _multicall\n    teardown.throw(exception)\n  File \"/home/ubuntu/actions-runner/_work/sdcore-tests/sdcore-tests/.tox/integration/lib/python3.10/site-packages/pluggy/_callers.py\", line 53, in run_old_style_hookwrapper\n    return result.get_result()\n  File \"/home/ubuntu/actions-runner/_work/sdcore-tests/sdcore-tests/.tox/integration/lib/python3.10/site-packages/pluggy/_result.py\", line 103, in get_result\n    raise exc.with_traceback(tb)\n  File \"/home/ubuntu/actions-runner/_work/sdcore-tests/sdcore-tests/.tox/integration/lib/python3.10/site-packages/pluggy/_callers.py\", line 38, in run_old_style_hookwrapper\n    res = yield\n  File \"/home/ubuntu/actions-runner/_work/sdcore-tests/sdcore-tests/.tox/integration/lib/python3.10/site-packages/pluggy/_callers.py\", line 139, in _multicall\n    teardown.throw(exception)\n  File \"/home/ubuntu/actions-runner/_work/sdcore-tests/sdcore-tests/.tox/integration/lib/python3.10/site-packages/_pytest/capture.py\", line 900, in pytest_runtest_call\n    return (yield)\n  File \"/home/ubuntu/actions-runner/_work/sdcore-tests/sdcore-tests/.tox/integration/lib/python3.10/site-packages/pluggy/_callers.py\", line 139, in _multicall\n    teardown.throw(exception)\n  File \"/home/ubuntu/actions-runner/_work/sdcore-tests/sdcore-tests/.tox/integration/lib/python3.10/site-packages/_pytest/skipping.py\", line 263, in pytest_runtest_call\n    return (yield)\n  File \"/home/ubuntu/actions-runner/_work/sdcore-tests/sdcore-tests/.tox/integration/lib/python3.10/site-packages/pluggy/_callers.py\", line 121, in _multicall\n    res = hook_impl.function(*args)\n  File \"/home/ubuntu/actions-runner/_work/sdcore-tests/sdcore-tests/.tox/integration/lib/python3.10/site-packages/_pytest/runner.py\", line 178, in pytest_runtest_call\n    item.runtest()\n  File \"/home/ubuntu/actions-runner/_work/sdcore-tests/sdcore-tests/.tox/integration/lib/python3.10/site-packages/_pytest/python.py\", line 1670, in runtest\n    self.ihook.pytest_pyfunc_call(pyfuncitem=self)\n  File \"/home/ubuntu/actions-runner/_work/sdcore-tests/sdcore-tests/.tox/integration/lib/python3.10/site-packages/pluggy/_hooks.py\", line 512, in __call__\n    return self._hookexec(self.name, self._hookimpls.copy(), kwargs, firstresult)\n  File \"/home/ubuntu/actions-runner/_work/sdcore-tests/sdcore-tests/.tox/integration/lib/python3.10/site-packages/pluggy/_manager.py\", line 120, in _hookexec\n    return self._inner_hookexec(hook_name, methods, kwargs, firstresult)\n  File \"/home/ubuntu/actions-runner/_work/sdcore-tests/sdcore-tests/.tox/integration/lib/python3.10/site-packages/pluggy/_callers.py\", line 167, in _multicall\n    raise exception\n  File \"/home/ubuntu/actions-runner/_work/sdcore-tests/sdcore-tests/.tox/integration/lib/python3.10/site-packages/pluggy/_callers.py\", line 139, in _multicall\n    teardown.throw(exception)\n  File \"/home/ubuntu/actions-runner/_work/sdcore-tests/sdcore-tests/.tox/integration/lib/python3.10/site-packages/pluggy/_callers.py\", line 53, in run_old_style_hookwrapper\n    return result.get_result()\n  File \"/home/ubuntu/actions-runner/_work/sdcore-tests/sdcore-tests/.tox/integration/lib/python3.10/site-packages/pluggy/_result.py\", line 103, in get_result\n    raise exc.with_traceback(tb)\n  File \"/home/ubuntu/actions-runner/_work/sdcore-tests/sdcore-tests/.tox/integration/lib/python3.10/site-packages/pluggy/_callers.py\", line 38, in run_old_style_hookwrapper\n    res = yield\n  File \"/home/ubuntu/actions-runner/_work/sdcore-tests/sdcore-tests/.tox/integration/lib/python3.10/site-packages/pluggy/_callers.py\", line 121, in _multicall\n    res = hook_impl.function(*args)\n  File \"/home/ubuntu/actions-runner/_work/sdcore-tests/sdcore-tests/.tox/integration/lib/python3.10/site-packages/_pytest/python.py\", line 156, in pytest_pyfunc_call\n    result = testfunction(**testargs)\n  File \"/home/ubuntu/actions-runner/_work/sdcore-tests/sdcore-tests/.tox/integration/lib/python3.10/site-packages/pytest_asyncio/plugin.py\", line 529, in inner\n    _loop.run_until_complete(task)\n  File \"/usr/lib/python3.10/asyncio/base_events.py\", line 649, in run_until_complete\n    return future.result()\n  File \"/home/ubuntu/actions-runner/_work/sdcore-tests/sdcore-tests/tests/integration/test_integration.py\", line 45, in test_given_sdcore_terraform_module_when_deploy_then_status_is_active\n    self._deploy_sdcore()\n  File \"/home/ubuntu/actions-runner/_work/sdcore-tests/sdcore-tests/tests/integration/test_integration.py\", line 122, in _deploy_sdcore\n    tf_client.apply()\n  File \"/home/ubuntu/actions-runner/_work/sdcore-tests/sdcore-tests/tests/integration/terraform_helper.py\", line 76, in apply\n    raise TerraformError(\ntests.integration.terraform_helper.TerraformError: Error running `terraform apply`","flaky":false,"newFailed":false,"newBroken":true,"newPassed":false,"retriesCount":0,"retriesStatusChange":false,"beforeStages":[{"name":"event_loop","time":{"start":1750473200057,"stop":1750473200058,"duration":1},"status":"passed","steps":[],"attachments":[],"parameters":[],"shouldDisplayMessage":false,"stepsCount":0,"attachmentsCount":0,"hasContent":false,"attachmentStep":false},{"name":"_xunit_setup_class_fixture_TestSDCoreBundle","time":{"start":1750473200058,"stop":1750473200992,"duration":934},"status":"passed","steps":[],"attachments":[],"parameters":[],"shouldDisplayMessage":false,"stepsCount":0,"attachmentsCount":0,"hasContent":false,"attachmentStep":false},{"name":"abort_on_fail","time":{"start":1750473200993,"stop":1750473200993,"duration":0},"status":"passed","steps":[],"attachments":[],"parameters":[],"shouldDisplayMessage":false,"stepsCount":0,"attachmentsCount":0,"hasContent":false,"attachmentStep":false}],"testStage":{"status":"broken","statusMessage":"tests.integration.terraform_helper.TerraformError: Error running `terraform apply`","statusTrace":"Traceback (most recent call last):\n  File \"/home/ubuntu/actions-runner/_work/sdcore-tests/sdcore-tests/tests/integration/terraform_helper.py\", line 74, in apply\n    self._run_terraform_cmd(TerraformCommands.apply, *args)\n  File \"/home/ubuntu/actions-runner/_work/sdcore-tests/sdcore-tests/tests/integration/terraform_helper.py\", line 100, in _run_terraform_cmd\n    return check_call([TERRAFORM_APP_NAME, terraform_command, *args], cwd=self.work_dir)\n  File \"/usr/lib/python3.10/subprocess.py\", line 369, in check_call\n    raise CalledProcessError(retcode, cmd)\nsubprocess.CalledProcessError: Command '['terraform', <TerraformCommands.apply: 'apply'>, '-auto-approve']' returned non-zero exit status 1.\n\nThe above exception was the direct cause of the following exception:\n\nTraceback (most recent call last):\n  File \"/home/ubuntu/actions-runner/_work/sdcore-tests/sdcore-tests/.tox/integration/lib/python3.10/site-packages/_pytest/runner.py\", line 344, in from_call\n    result: TResult | None = func()\n  File \"/home/ubuntu/actions-runner/_work/sdcore-tests/sdcore-tests/.tox/integration/lib/python3.10/site-packages/_pytest/runner.py\", line 246, in <lambda>\n    lambda: runtest_hook(item=item, **kwds), when=when, reraise=reraise\n  File \"/home/ubuntu/actions-runner/_work/sdcore-tests/sdcore-tests/.tox/integration/lib/python3.10/site-packages/pluggy/_hooks.py\", line 512, in __call__\n    return self._hookexec(self.name, self._hookimpls.copy(), kwargs, firstresult)\n  File \"/home/ubuntu/actions-runner/_work/sdcore-tests/sdcore-tests/.tox/integration/lib/python3.10/site-packages/pluggy/_manager.py\", line 120, in _hookexec\n    return self._inner_hookexec(hook_name, methods, kwargs, firstresult)\n  File \"/home/ubuntu/actions-runner/_work/sdcore-tests/sdcore-tests/.tox/integration/lib/python3.10/site-packages/pluggy/_callers.py\", line 167, in _multicall\n    raise exception\n  File \"/home/ubuntu/actions-runner/_work/sdcore-tests/sdcore-tests/.tox/integration/lib/python3.10/site-packages/pluggy/_callers.py\", line 139, in _multicall\n    teardown.throw(exception)\n  File \"/home/ubuntu/actions-runner/_work/sdcore-tests/sdcore-tests/.tox/integration/lib/python3.10/site-packages/_pytest/logging.py\", line 850, in pytest_runtest_call\n    yield\n  File \"/home/ubuntu/actions-runner/_work/sdcore-tests/sdcore-tests/.tox/integration/lib/python3.10/site-packages/pluggy/_callers.py\", line 139, in _multicall\n    teardown.throw(exception)\n  File \"/home/ubuntu/actions-runner/_work/sdcore-tests/sdcore-tests/.tox/integration/lib/python3.10/site-packages/pluggy/_callers.py\", line 53, in run_old_style_hookwrapper\n    return result.get_result()\n  File \"/home/ubuntu/actions-runner/_work/sdcore-tests/sdcore-tests/.tox/integration/lib/python3.10/site-packages/pluggy/_result.py\", line 103, in get_result\n    raise exc.with_traceback(tb)\n  File \"/home/ubuntu/actions-runner/_work/sdcore-tests/sdcore-tests/.tox/integration/lib/python3.10/site-packages/pluggy/_callers.py\", line 38, in run_old_style_hookwrapper\n    res = yield\n  File \"/home/ubuntu/actions-runner/_work/sdcore-tests/sdcore-tests/.tox/integration/lib/python3.10/site-packages/pluggy/_callers.py\", line 139, in _multicall\n    teardown.throw(exception)\n  File \"/home/ubuntu/actions-runner/_work/sdcore-tests/sdcore-tests/.tox/integration/lib/python3.10/site-packages/_pytest/capture.py\", line 900, in pytest_runtest_call\n    return (yield)\n  File \"/home/ubuntu/actions-runner/_work/sdcore-tests/sdcore-tests/.tox/integration/lib/python3.10/site-packages/pluggy/_callers.py\", line 139, in _multicall\n    teardown.throw(exception)\n  File \"/home/ubuntu/actions-runner/_work/sdcore-tests/sdcore-tests/.tox/integration/lib/python3.10/site-packages/_pytest/skipping.py\", line 263, in pytest_runtest_call\n    return (yield)\n  File \"/home/ubuntu/actions-runner/_work/sdcore-tests/sdcore-tests/.tox/integration/lib/python3.10/site-packages/pluggy/_callers.py\", line 121, in _multicall\n    res = hook_impl.function(*args)\n  File \"/home/ubuntu/actions-runner/_work/sdcore-tests/sdcore-tests/.tox/integration/lib/python3.10/site-packages/_pytest/runner.py\", line 178, in pytest_runtest_call\n    item.runtest()\n  File \"/home/ubuntu/actions-runner/_work/sdcore-tests/sdcore-tests/.tox/integration/lib/python3.10/site-packages/_pytest/python.py\", line 1670, in runtest\n    self.ihook.pytest_pyfunc_call(pyfuncitem=self)\n  File \"/home/ubuntu/actions-runner/_work/sdcore-tests/sdcore-tests/.tox/integration/lib/python3.10/site-packages/pluggy/_hooks.py\", line 512, in __call__\n    return self._hookexec(self.name, self._hookimpls.copy(), kwargs, firstresult)\n  File \"/home/ubuntu/actions-runner/_work/sdcore-tests/sdcore-tests/.tox/integration/lib/python3.10/site-packages/pluggy/_manager.py\", line 120, in _hookexec\n    return self._inner_hookexec(hook_name, methods, kwargs, firstresult)\n  File \"/home/ubuntu/actions-runner/_work/sdcore-tests/sdcore-tests/.tox/integration/lib/python3.10/site-packages/pluggy/_callers.py\", line 167, in _multicall\n    raise exception\n  File \"/home/ubuntu/actions-runner/_work/sdcore-tests/sdcore-tests/.tox/integration/lib/python3.10/site-packages/pluggy/_callers.py\", line 139, in _multicall\n    teardown.throw(exception)\n  File \"/home/ubuntu/actions-runner/_work/sdcore-tests/sdcore-tests/.tox/integration/lib/python3.10/site-packages/pluggy/_callers.py\", line 53, in run_old_style_hookwrapper\n    return result.get_result()\n  File \"/home/ubuntu/actions-runner/_work/sdcore-tests/sdcore-tests/.tox/integration/lib/python3.10/site-packages/pluggy/_result.py\", line 103, in get_result\n    raise exc.with_traceback(tb)\n  File \"/home/ubuntu/actions-runner/_work/sdcore-tests/sdcore-tests/.tox/integration/lib/python3.10/site-packages/pluggy/_callers.py\", line 38, in run_old_style_hookwrapper\n    res = yield\n  File \"/home/ubuntu/actions-runner/_work/sdcore-tests/sdcore-tests/.tox/integration/lib/python3.10/site-packages/pluggy/_callers.py\", line 121, in _multicall\n    res = hook_impl.function(*args)\n  File \"/home/ubuntu/actions-runner/_work/sdcore-tests/sdcore-tests/.tox/integration/lib/python3.10/site-packages/_pytest/python.py\", line 156, in pytest_pyfunc_call\n    result = testfunction(**testargs)\n  File \"/home/ubuntu/actions-runner/_work/sdcore-tests/sdcore-tests/.tox/integration/lib/python3.10/site-packages/pytest_asyncio/plugin.py\", line 529, in inner\n    _loop.run_until_complete(task)\n  File \"/usr/lib/python3.10/asyncio/base_events.py\", line 649, in run_until_complete\n    return future.result()\n  File \"/home/ubuntu/actions-runner/_work/sdcore-tests/sdcore-tests/tests/integration/test_integration.py\", line 45, in test_given_sdcore_terraform_module_when_deploy_then_status_is_active\n    self._deploy_sdcore()\n  File \"/home/ubuntu/actions-runner/_work/sdcore-tests/sdcore-tests/tests/integration/test_integration.py\", line 122, in _deploy_sdcore\n    tf_client.apply()\n  File \"/home/ubuntu/actions-runner/_work/sdcore-tests/sdcore-tests/tests/integration/terraform_helper.py\", line 76, in apply\n    raise TerraformError(\ntests.integration.terraform_helper.TerraformError: Error running `terraform apply`","steps":[],"attachments":[{"uid":"1864c589ec833468","name":"log","source":"1864c589ec833468.txt","type":"text/plain","size":563}],"parameters":[],"shouldDisplayMessage":true,"stepsCount":0,"attachmentsCount":1,"hasContent":true,"attachmentStep":false},"afterStages":[{"name":"abort_on_fail::0","time":{"start":1750473494790,"stop":1750473494790,"duration":0},"status":"passed","steps":[],"attachments":[],"parameters":[],"shouldDisplayMessage":false,"stepsCount":0,"attachmentsCount":0,"hasContent":false,"attachmentStep":false},{"name":"_xunit_setup_class_fixture_TestSDCoreBundle::0","time":{"start":1750473680950,"stop":1750473680950,"duration":0},"status":"passed","steps":[],"attachments":[],"parameters":[],"shouldDisplayMessage":false,"stepsCount":0,"attachmentsCount":0,"hasContent":false,"attachmentStep":false},{"name":"event_loop::2","time":{"start":1750473680951,"stop":1750473680951,"duration":0},"status":"passed","steps":[],"attachments":[],"parameters":[],"shouldDisplayMessage":false,"stepsCount":0,"attachmentsCount":0,"hasContent":false,"attachmentStep":false},{"name":"event_loop::_close_event_loop","time":{"start":1750473680951,"stop":1750473680951,"duration":0},"status":"passed","steps":[],"attachments":[],"parameters":[],"shouldDisplayMessage":false,"stepsCount":0,"attachmentsCount":0,"hasContent":false,"attachmentStep":false},{"name":"event_loop::_provide_clean_event_loop","time":{"start":1750473680951,"stop":1750473680951,"duration":0},"status":"passed","steps":[],"attachments":[],"parameters":[],"shouldDisplayMessage":false,"stepsCount":0,"attachmentsCount":0,"hasContent":false,"attachmentStep":false}],"labels":[{"name":"tag","value":"abort_on_fail"},{"name":"tag","value":"asyncio"},{"name":"parentSuite","value":"tests.integration"},{"name":"suite","value":"test_integration"},{"name":"subSuite","value":"TestSDCoreBundle"},{"name":"host","value":"github-runner"},{"name":"thread","value":"15740-MainThread"},{"name":"framework","value":"pytest"},{"name":"language","value":"cpython3"},{"name":"package","value":"tests.integration.test_integration"},{"name":"resultFormat","value":"allure2"}],"parameters":[],"links":[],"hidden":false,"retry":false,"extra":{"severity":"normal","retries":[],"categories":[{"name":"Test defects","matchedStatuses":[],"flaky":false}],"history":{"statistic":{"failed":0,"broken":2,"skipped":0,"passed":1,"unknown":0,"total":3},"items":[{"uid":"2be1598725d55a5e","reportUrl":"https://canonical.github.io/sdcore-tests/2488//#testresult/2be1598725d55a5e","status":"passed","time":{"start":1750386935842,"stop":1750387382870,"duration":447028}},{"uid":"1c46d143828fc2c6","reportUrl":"https://canonical.github.io/sdcore-tests/2486//#testresult/1c46d143828fc2c6","status":"broken","statusDetails":"TimeoutError: Timed out waiting for Juju model to be ready!","time":{"start":1750214046422,"stop":1750215217339,"duration":1170917}}]},"tags":["asyncio","abort_on_fail"]},"source":"b7b3dfab69850c4e.json","parameterValues":[]}